<robot name="myrobot">
    <material name="yellow">
        <color rgba="0.8 0.8 0.0 0.5"/>
    </material>

    <material name="red">
        <color rgba="1.0 0.0 0.0 1"/>
    </material>

    <link name="base_footprint">
        <visual>
            <geometry>
                <geometry>
                    <sphere radius="0.001"/>
                </geometry>
            </geometry>
        </visual>

    </link>


    <link name="base_link">
        <visual>
            <geometry>
                <box size="0.5 0.3 0.1"/>
            </geometry>
            <material name="yellow"/>
        </visual>
    </link>

    <joint name="base" type="fixed">
        <parent link="base_footprint"/>
        <child link="base_link"/>
        
        <origin xyz="0.0 0.0 0.05" rpy="0.0 0.0 0.0"/>
    </joint>

    <link name="camera">
        <visual>
            <geometry>
                <box size="0.02 0.05 0.05"/>
            </geometry>
            <material name="red"/>
        </visual>
    </link>

    <joint name="camera2baselink" type="continuous">
        <parent link="base_link"/>
        <child link="camera"/>
        
        <origin xyz="0.24 0.0 0.075" rpy="0.0 0.0 0.0"/>

        <axis xyz="0.0 0.0 1"/>
    </joint>
</robot>